<mujoco model="hybrid_20x20_wMin20_wMax40_deadD3_aaMin5_ttMin3_atMin30_seed7">
  <option timestep="0.01"/>

  <worldbody>
    <geom name="floor" type="plane" size="10.0 10.0 0.1" rgba="0.5 0.5 0.5 1"/>

    <body name="ob_0_19" pos="9.5000 9.5000 0.500">  <geom type="box" size="0.5000 0.5000 0.500"         rgba="1 0 0 1" contype="1" conaffinity="1"/></body>
        <body name="ob_1_5" pos="-4.5000 8.5000 0.500">  <geom type="box" size="0.5000 0.5000 0.500"         rgba="1 0 0 1" contype="1" conaffinity="1"/></body>
        <body name="ob_2_3" pos="-6.5000 7.5000 0.500">  <geom type="box" size="0.5000 0.5000 0.500"         rgba="1 0 0 1" contype="1" conaffinity="1"/></body>
        <body name="ob_2_16" pos="6.5000 7.5000 0.500">  <geom type="box" size="0.5000 0.5000 0.500"         rgba="1 0 0 1" contype="1" conaffinity="1"/></body>
        <body name="ob_3_5" pos="-4.5000 6.5000 0.500">  <geom type="box" size="0.5000 0.5000 0.500"         rgba="1 0 0 1" contype="1" conaffinity="1"/></body>
        <body name="ob_3_7" pos="-2.5000 6.5000 0.500">  <geom type="box" size="0.5000 0.5000 0.500"         rgba="1 0 0 1" contype="1" conaffinity="1"/></body>
        <body name="ob_4_4" pos="-5.5000 5.5000 0.500">  <geom type="box" size="0.5000 0.5000 0.500"         rgba="1 0 0 1" contype="1" conaffinity="1"/></body>
        <body name="ob_4_7" pos="-2.5000 5.5000 0.500">  <geom type="box" size="0.5000 0.5000 0.500"         rgba="1 0 0 1" contype="1" conaffinity="1"/></body>
        <body name="ob_5_5" pos="-4.5000 4.5000 0.500">  <geom type="box" size="0.5000 0.5000 0.500"         rgba="1 0 0 1" contype="1" conaffinity="1"/></body>
        <body name="ob_5_6" pos="-3.5000 4.5000 0.500">  <geom type="box" size="0.5000 0.5000 0.500"         rgba="1 0 0 1" contype="1" conaffinity="1"/></body>
        <body name="ob_7_19" pos="9.5000 2.5000 0.500">  <geom type="box" size="0.5000 0.5000 0.500"         rgba="1 0 0 1" contype="1" conaffinity="1"/></body>
        <body name="ob_10_4" pos="-5.5000 -0.5000 0.500">  <geom type="box" size="0.5000 0.5000 0.500"         rgba="1 0 0 1" contype="1" conaffinity="1"/></body>
        <body name="ob_11_1" pos="-8.5000 -1.5000 0.500">  <geom type="box" size="0.5000 0.5000 0.500"         rgba="1 0 0 1" contype="1" conaffinity="1"/></body>
        <body name="ob_11_4" pos="-5.5000 -1.5000 0.500">  <geom type="box" size="0.5000 0.5000 0.500"         rgba="1 0 0 1" contype="1" conaffinity="1"/></body>
        <body name="ob_12_3" pos="-6.5000 -2.5000 0.500">  <geom type="box" size="0.5000 0.5000 0.500"         rgba="1 0 0 1" contype="1" conaffinity="1"/></body>
        <body name="ob_12_16" pos="6.5000 -2.5000 0.500">  <geom type="box" size="0.5000 0.5000 0.500"         rgba="1 0 0 1" contype="1" conaffinity="1"/></body>
        <body name="ob_13_9" pos="-0.5000 -3.5000 0.500">  <geom type="box" size="0.5000 0.5000 0.500"         rgba="1 0 0 1" contype="1" conaffinity="1"/></body>
        <body name="ob_13_11" pos="1.5000 -3.5000 0.500">  <geom type="box" size="0.5000 0.5000 0.500"         rgba="1 0 0 1" contype="1" conaffinity="1"/></body>
        <body name="ob_14_17" pos="7.5000 -4.5000 0.500">  <geom type="box" size="0.5000 0.5000 0.500"         rgba="1 0 0 1" contype="1" conaffinity="1"/></body>
        <body name="ob_15_14" pos="4.5000 -5.5000 0.500">  <geom type="box" size="0.5000 0.5000 0.500"         rgba="1 0 0 1" contype="1" conaffinity="1"/></body>
        <body name="ob_16_1" pos="-8.5000 -6.5000 0.500">  <geom type="box" size="0.5000 0.5000 0.500"         rgba="1 0 0 1" contype="1" conaffinity="1"/></body>
        <body name="ob_17_12" pos="2.5000 -7.5000 0.500">  <geom type="box" size="0.5000 0.5000 0.500"         rgba="1 0 0 1" contype="1" conaffinity="1"/></body>
        <body name="ob_18_14" pos="4.5000 -8.5000 0.500">  <geom type="box" size="0.5000 0.5000 0.500"         rgba="1 0 0 1" contype="1" conaffinity="1"/></body>
        <body name="ob_19_5" pos="-4.5000 -9.5000 0.500">  <geom type="box" size="0.5000 0.5000 0.500"         rgba="1 0 0 1" contype="1" conaffinity="1"/></body>
    
            <body name="agent_0" pos="9.5000 -6.5000 0.5">
                <joint name="agent_0_j1" type="slide" axis="1 0 0"/>
                <joint name="agent_0_j2" type="slide" axis="0 1 0"/>
                <geom  name="agent_geom_0" type="box" size="0.3 0.3 0.3" rgba="1 1 0 1"/>
            </body>
            

            <body name="target_0" pos="-4.5000 5.5000 0.25">
                <geom name="target_geom_0" type="sphere" size="0.25"
                      rgba="0 1 0 1" contype="0" conaffinity="0"/>
            </body>
            
  </worldbody>

</mujoco>