<mujoco model="hybrid_20x20_wMin120_wMax160_deadD3_aaMin5_ttMin3_atMin4_seed7">
  <option timestep="0.01"/>

  <worldbody>
    <geom name="floor" type="plane" size="10.0 10.0 0.1" rgba="0.5 0.5 0.5 1"/>

    <body name="ob_0_5" pos="-4.5000 9.5000 0.500">  <geom type="box" size="0.5000 0.5000 0.500"         rgba="1 0 0 1" contype="1" conaffinity="1"/></body>
        <body name="ob_0_17" pos="7.5000 9.5000 0.500">  <geom type="box" size="0.5000 0.5000 0.500"         rgba="1 0 0 1" contype="1" conaffinity="1"/></body>
        <body name="ob_0_19" pos="9.5000 9.5000 0.500">  <geom type="box" size="0.5000 0.5000 0.500"         rgba="1 0 0 1" contype="1" conaffinity="1"/></body>
        <body name="ob_1_0" pos="-9.5000 8.5000 0.500">  <geom type="box" size="0.5000 0.5000 0.500"         rgba="1 0 0 1" contype="1" conaffinity="1"/></body>
        <body name="ob_1_3" pos="-6.5000 8.5000 0.500">  <geom type="box" size="0.5000 0.5000 0.500"         rgba="1 0 0 1" contype="1" conaffinity="1"/></body>
        <body name="ob_1_5" pos="-4.5000 8.5000 0.500">  <geom type="box" size="0.5000 0.5000 0.500"         rgba="1 0 0 1" contype="1" conaffinity="1"/></body>
        <body name="ob_1_10" pos="0.5000 8.5000 0.500">  <geom type="box" size="0.5000 0.5000 0.500"         rgba="1 0 0 1" contype="1" conaffinity="1"/></body>
        <body name="ob_1_13" pos="3.5000 8.5000 0.500">  <geom type="box" size="0.5000 0.5000 0.500"         rgba="1 0 0 1" contype="1" conaffinity="1"/></body>
        <body name="ob_2_4" pos="-5.5000 7.5000 0.500">  <geom type="box" size="0.5000 0.5000 0.500"         rgba="1 0 0 1" contype="1" conaffinity="1"/></body>
        <body name="ob_2_7" pos="-2.5000 7.5000 0.500">  <geom type="box" size="0.5000 0.5000 0.500"         rgba="1 0 0 1" contype="1" conaffinity="1"/></body>
        <body name="ob_2_10" pos="0.5000 7.5000 0.500">  <geom type="box" size="0.5000 0.5000 0.500"         rgba="1 0 0 1" contype="1" conaffinity="1"/></body>
        <body name="ob_2_12" pos="2.5000 7.5000 0.500">  <geom type="box" size="0.5000 0.5000 0.500"         rgba="1 0 0 1" contype="1" conaffinity="1"/></body>
        <body name="ob_3_0" pos="-9.5000 6.5000 0.500">  <geom type="box" size="0.5000 0.5000 0.500"         rgba="1 0 0 1" contype="1" conaffinity="1"/></body>
        <body name="ob_3_2" pos="-7.5000 6.5000 0.500">  <geom type="box" size="0.5000 0.5000 0.500"         rgba="1 0 0 1" contype="1" conaffinity="1"/></body>
        <body name="ob_3_5" pos="-4.5000 6.5000 0.500">  <geom type="box" size="0.5000 0.5000 0.500"         rgba="1 0 0 1" contype="1" conaffinity="1"/></body>
        <body name="ob_3_6" pos="-3.5000 6.5000 0.500">  <geom type="box" size="0.5000 0.5000 0.500"         rgba="1 0 0 1" contype="1" conaffinity="1"/></body>
        <body name="ob_3_7" pos="-2.5000 6.5000 0.500">  <geom type="box" size="0.5000 0.5000 0.500"         rgba="1 0 0 1" contype="1" conaffinity="1"/></body>
        <body name="ob_3_14" pos="4.5000 6.5000 0.500">  <geom type="box" size="0.5000 0.5000 0.500"         rgba="1 0 0 1" contype="1" conaffinity="1"/></body>
        <body name="ob_3_15" pos="5.5000 6.5000 0.500">  <geom type="box" size="0.5000 0.5000 0.500"         rgba="1 0 0 1" contype="1" conaffinity="1"/></body>
        <body name="ob_3_17" pos="7.5000 6.5000 0.500">  <geom type="box" size="0.5000 0.5000 0.500"         rgba="1 0 0 1" contype="1" conaffinity="1"/></body>
        <body name="ob_3_18" pos="8.5000 6.5000 0.500">  <geom type="box" size="0.5000 0.5000 0.500"         rgba="1 0 0 1" contype="1" conaffinity="1"/></body>
        <body name="ob_4_1" pos="-8.5000 5.5000 0.500">  <geom type="box" size="0.5000 0.5000 0.500"         rgba="1 0 0 1" contype="1" conaffinity="1"/></body>
        <body name="ob_4_4" pos="-5.5000 5.5000 0.500">  <geom type="box" size="0.5000 0.5000 0.500"         rgba="1 0 0 1" contype="1" conaffinity="1"/></body>
        <body name="ob_4_5" pos="-4.5000 5.5000 0.500">  <geom type="box" size="0.5000 0.5000 0.500"         rgba="1 0 0 1" contype="1" conaffinity="1"/></body>
        <body name="ob_4_6" pos="-3.5000 5.5000 0.500">  <geom type="box" size="0.5000 0.5000 0.500"         rgba="1 0 0 1" contype="1" conaffinity="1"/></body>
        <body name="ob_4_7" pos="-2.5000 5.5000 0.500">  <geom type="box" size="0.5000 0.5000 0.500"         rgba="1 0 0 1" contype="1" conaffinity="1"/></body>
        <body name="ob_4_8" pos="-1.5000 5.5000 0.500">  <geom type="box" size="0.5000 0.5000 0.500"         rgba="1 0 0 1" contype="1" conaffinity="1"/></body>
        <body name="ob_4_12" pos="2.5000 5.5000 0.500">  <geom type="box" size="0.5000 0.5000 0.500"         rgba="1 0 0 1" contype="1" conaffinity="1"/></body>
        <body name="ob_4_18" pos="8.5000 5.5000 0.500">  <geom type="box" size="0.5000 0.5000 0.500"         rgba="1 0 0 1" contype="1" conaffinity="1"/></body>
        <body name="ob_4_19" pos="9.5000 5.5000 0.500">  <geom type="box" size="0.5000 0.5000 0.500"         rgba="1 0 0 1" contype="1" conaffinity="1"/></body>
        <body name="ob_5_4" pos="-5.5000 4.5000 0.500">  <geom type="box" size="0.5000 0.5000 0.500"         rgba="1 0 0 1" contype="1" conaffinity="1"/></body>
        <body name="ob_5_5" pos="-4.5000 4.5000 0.500">  <geom type="box" size="0.5000 0.5000 0.500"         rgba="1 0 0 1" contype="1" conaffinity="1"/></body>
        <body name="ob_5_6" pos="-3.5000 4.5000 0.500">  <geom type="box" size="0.5000 0.5000 0.500"         rgba="1 0 0 1" contype="1" conaffinity="1"/></body>
        <body name="ob_5_13" pos="3.5000 4.5000 0.500">  <geom type="box" size="0.5000 0.5000 0.500"         rgba="1 0 0 1" contype="1" conaffinity="1"/></body>
        <body name="ob_5_16" pos="6.5000 4.5000 0.500">  <geom type="box" size="0.5000 0.5000 0.500"         rgba="1 0 0 1" contype="1" conaffinity="1"/></body>
        <body name="ob_6_2" pos="-7.5000 3.5000 0.500">  <geom type="box" size="0.5000 0.5000 0.500"         rgba="1 0 0 1" contype="1" conaffinity="1"/></body>
        <body name="ob_6_5" pos="-4.5000 3.5000 0.500">  <geom type="box" size="0.5000 0.5000 0.500"         rgba="1 0 0 1" contype="1" conaffinity="1"/></body>
        <body name="ob_6_6" pos="-3.5000 3.5000 0.500">  <geom type="box" size="0.5000 0.5000 0.500"         rgba="1 0 0 1" contype="1" conaffinity="1"/></body>
        <body name="ob_6_10" pos="0.5000 3.5000 0.500">  <geom type="box" size="0.5000 0.5000 0.500"         rgba="1 0 0 1" contype="1" conaffinity="1"/></body>
        <body name="ob_6_12" pos="2.5000 3.5000 0.500">  <geom type="box" size="0.5000 0.5000 0.500"         rgba="1 0 0 1" contype="1" conaffinity="1"/></body>
        <body name="ob_6_18" pos="8.5000 3.5000 0.500">  <geom type="box" size="0.5000 0.5000 0.500"         rgba="1 0 0 1" contype="1" conaffinity="1"/></body>
        <body name="ob_7_0" pos="-9.5000 2.5000 0.500">  <geom type="box" size="0.5000 0.5000 0.500"         rgba="1 0 0 1" contype="1" conaffinity="1"/></body>
        <body name="ob_7_3" pos="-6.5000 2.5000 0.500">  <geom type="box" size="0.5000 0.5000 0.500"         rgba="1 0 0 1" contype="1" conaffinity="1"/></body>
        <body name="ob_7_5" pos="-4.5000 2.5000 0.500">  <geom type="box" size="0.5000 0.5000 0.500"         rgba="1 0 0 1" contype="1" conaffinity="1"/></body>
        <body name="ob_7_6" pos="-3.5000 2.5000 0.500">  <geom type="box" size="0.5000 0.5000 0.500"         rgba="1 0 0 1" contype="1" conaffinity="1"/></body>
        <body name="ob_7_7" pos="-2.5000 2.5000 0.500">  <geom type="box" size="0.5000 0.5000 0.500"         rgba="1 0 0 1" contype="1" conaffinity="1"/></body>
        <body name="ob_7_11" pos="1.5000 2.5000 0.500">  <geom type="box" size="0.5000 0.5000 0.500"         rgba="1 0 0 1" contype="1" conaffinity="1"/></body>
        <body name="ob_7_12" pos="2.5000 2.5000 0.500">  <geom type="box" size="0.5000 0.5000 0.500"         rgba="1 0 0 1" contype="1" conaffinity="1"/></body>
        <body name="ob_7_15" pos="5.5000 2.5000 0.500">  <geom type="box" size="0.5000 0.5000 0.500"         rgba="1 0 0 1" contype="1" conaffinity="1"/></body>
        <body name="ob_7_16" pos="6.5000 2.5000 0.500">  <geom type="box" size="0.5000 0.5000 0.500"         rgba="1 0 0 1" contype="1" conaffinity="1"/></body>
        <body name="ob_7_17" pos="7.5000 2.5000 0.500">  <geom type="box" size="0.5000 0.5000 0.500"         rgba="1 0 0 1" contype="1" conaffinity="1"/></body>
        <body name="ob_7_19" pos="9.5000 2.5000 0.500">  <geom type="box" size="0.5000 0.5000 0.500"         rgba="1 0 0 1" contype="1" conaffinity="1"/></body>
        <body name="ob_8_4" pos="-5.5000 1.5000 0.500">  <geom type="box" size="0.5000 0.5000 0.500"         rgba="1 0 0 1" contype="1" conaffinity="1"/></body>
        <body name="ob_8_5" pos="-4.5000 1.5000 0.500">  <geom type="box" size="0.5000 0.5000 0.500"         rgba="1 0 0 1" contype="1" conaffinity="1"/></body>
        <body name="ob_9_0" pos="-9.5000 0.5000 0.500">  <geom type="box" size="0.5000 0.5000 0.500"         rgba="1 0 0 1" contype="1" conaffinity="1"/></body>
        <body name="ob_9_7" pos="-2.5000 0.5000 0.500">  <geom type="box" size="0.5000 0.5000 0.500"         rgba="1 0 0 1" contype="1" conaffinity="1"/></body>
        <body name="ob_9_10" pos="0.5000 0.5000 0.500">  <geom type="box" size="0.5000 0.5000 0.500"         rgba="1 0 0 1" contype="1" conaffinity="1"/></body>
        <body name="ob_9_12" pos="2.5000 0.5000 0.500">  <geom type="box" size="0.5000 0.5000 0.500"         rgba="1 0 0 1" contype="1" conaffinity="1"/></body>
        <body name="ob_9_13" pos="3.5000 0.5000 0.500">  <geom type="box" size="0.5000 0.5000 0.500"         rgba="1 0 0 1" contype="1" conaffinity="1"/></body>
        <body name="ob_9_16" pos="6.5000 0.5000 0.500">  <geom type="box" size="0.5000 0.5000 0.500"         rgba="1 0 0 1" contype="1" conaffinity="1"/></body>
        <body name="ob_9_19" pos="9.5000 0.5000 0.500">  <geom type="box" size="0.5000 0.5000 0.500"         rgba="1 0 0 1" contype="1" conaffinity="1"/></body>
        <body name="ob_10_2" pos="-7.5000 -0.5000 0.500">  <geom type="box" size="0.5000 0.5000 0.500"         rgba="1 0 0 1" contype="1" conaffinity="1"/></body>
        <body name="ob_10_11" pos="1.5000 -0.5000 0.500">  <geom type="box" size="0.5000 0.5000 0.500"         rgba="1 0 0 1" contype="1" conaffinity="1"/></body>
        <body name="ob_10_13" pos="3.5000 -0.5000 0.500">  <geom type="box" size="0.5000 0.5000 0.500"         rgba="1 0 0 1" contype="1" conaffinity="1"/></body>
        <body name="ob_10_16" pos="6.5000 -0.5000 0.500">  <geom type="box" size="0.5000 0.5000 0.500"         rgba="1 0 0 1" contype="1" conaffinity="1"/></body>
        <body name="ob_11_1" pos="-8.5000 -1.5000 0.500">  <geom type="box" size="0.5000 0.5000 0.500"         rgba="1 0 0 1" contype="1" conaffinity="1"/></body>
        <body name="ob_11_6" pos="-3.5000 -1.5000 0.500">  <geom type="box" size="0.5000 0.5000 0.500"         rgba="1 0 0 1" contype="1" conaffinity="1"/></body>
        <body name="ob_11_8" pos="-1.5000 -1.5000 0.500">  <geom type="box" size="0.5000 0.5000 0.500"         rgba="1 0 0 1" contype="1" conaffinity="1"/></body>
        <body name="ob_11_10" pos="0.5000 -1.5000 0.500">  <geom type="box" size="0.5000 0.5000 0.500"         rgba="1 0 0 1" contype="1" conaffinity="1"/></body>
        <body name="ob_11_17" pos="7.5000 -1.5000 0.500">  <geom type="box" size="0.5000 0.5000 0.500"         rgba="1 0 0 1" contype="1" conaffinity="1"/></body>
        <body name="ob_11_18" pos="8.5000 -1.5000 0.500">  <geom type="box" size="0.5000 0.5000 0.500"         rgba="1 0 0 1" contype="1" conaffinity="1"/></body>
        <body name="ob_12_1" pos="-8.5000 -2.5000 0.500">  <geom type="box" size="0.5000 0.5000 0.500"         rgba="1 0 0 1" contype="1" conaffinity="1"/></body>
        <body name="ob_12_2" pos="-7.5000 -2.5000 0.500">  <geom type="box" size="0.5000 0.5000 0.500"         rgba="1 0 0 1" contype="1" conaffinity="1"/></body>
        <body name="ob_12_4" pos="-5.5000 -2.5000 0.500">  <geom type="box" size="0.5000 0.5000 0.500"         rgba="1 0 0 1" contype="1" conaffinity="1"/></body>
        <body name="ob_12_5" pos="-4.5000 -2.5000 0.500">  <geom type="box" size="0.5000 0.5000 0.500"         rgba="1 0 0 1" contype="1" conaffinity="1"/></body>
        <body name="ob_12_8" pos="-1.5000 -2.5000 0.500">  <geom type="box" size="0.5000 0.5000 0.500"         rgba="1 0 0 1" contype="1" conaffinity="1"/></body>
        <body name="ob_12_12" pos="2.5000 -2.5000 0.500">  <geom type="box" size="0.5000 0.5000 0.500"         rgba="1 0 0 1" contype="1" conaffinity="1"/></body>
        <body name="ob_12_15" pos="5.5000 -2.5000 0.500">  <geom type="box" size="0.5000 0.5000 0.500"         rgba="1 0 0 1" contype="1" conaffinity="1"/></body>
        <body name="ob_12_16" pos="6.5000 -2.5000 0.500">  <geom type="box" size="0.5000 0.5000 0.500"         rgba="1 0 0 1" contype="1" conaffinity="1"/></body>
        <body name="ob_12_18" pos="8.5000 -2.5000 0.500">  <geom type="box" size="0.5000 0.5000 0.500"         rgba="1 0 0 1" contype="1" conaffinity="1"/></body>
        <body name="ob_12_19" pos="9.5000 -2.5000 0.500">  <geom type="box" size="0.5000 0.5000 0.500"         rgba="1 0 0 1" contype="1" conaffinity="1"/></body>
        <body name="ob_13_0" pos="-9.5000 -3.5000 0.500">  <geom type="box" size="0.5000 0.5000 0.500"         rgba="1 0 0 1" contype="1" conaffinity="1"/></body>
        <body name="ob_13_2" pos="-7.5000 -3.5000 0.500">  <geom type="box" size="0.5000 0.5000 0.500"         rgba="1 0 0 1" contype="1" conaffinity="1"/></body>
        <body name="ob_13_5" pos="-4.5000 -3.5000 0.500">  <geom type="box" size="0.5000 0.5000 0.500"         rgba="1 0 0 1" contype="1" conaffinity="1"/></body>
        <body name="ob_13_8" pos="-1.5000 -3.5000 0.500">  <geom type="box" size="0.5000 0.5000 0.500"         rgba="1 0 0 1" contype="1" conaffinity="1"/></body>
        <body name="ob_13_10" pos="0.5000 -3.5000 0.500">  <geom type="box" size="0.5000 0.5000 0.500"         rgba="1 0 0 1" contype="1" conaffinity="1"/></body>
        <body name="ob_13_13" pos="3.5000 -3.5000 0.500">  <geom type="box" size="0.5000 0.5000 0.500"         rgba="1 0 0 1" contype="1" conaffinity="1"/></body>
        <body name="ob_13_18" pos="8.5000 -3.5000 0.500">  <geom type="box" size="0.5000 0.5000 0.500"         rgba="1 0 0 1" contype="1" conaffinity="1"/></body>
        <body name="ob_13_19" pos="9.5000 -3.5000 0.500">  <geom type="box" size="0.5000 0.5000 0.500"         rgba="1 0 0 1" contype="1" conaffinity="1"/></body>
        <body name="ob_14_4" pos="-5.5000 -4.5000 0.500">  <geom type="box" size="0.5000 0.5000 0.500"         rgba="1 0 0 1" contype="1" conaffinity="1"/></body>
        <body name="ob_14_19" pos="9.5000 -4.5000 0.500">  <geom type="box" size="0.5000 0.5000 0.500"         rgba="1 0 0 1" contype="1" conaffinity="1"/></body>
        <body name="ob_15_1" pos="-8.5000 -5.5000 0.500">  <geom type="box" size="0.5000 0.5000 0.500"         rgba="1 0 0 1" contype="1" conaffinity="1"/></body>
        <body name="ob_15_2" pos="-7.5000 -5.5000 0.500">  <geom type="box" size="0.5000 0.5000 0.500"         rgba="1 0 0 1" contype="1" conaffinity="1"/></body>
        <body name="ob_15_4" pos="-5.5000 -5.5000 0.500">  <geom type="box" size="0.5000 0.5000 0.500"         rgba="1 0 0 1" contype="1" conaffinity="1"/></body>
        <body name="ob_15_6" pos="-3.5000 -5.5000 0.500">  <geom type="box" size="0.5000 0.5000 0.500"         rgba="1 0 0 1" contype="1" conaffinity="1"/></body>
        <body name="ob_15_7" pos="-2.5000 -5.5000 0.500">  <geom type="box" size="0.5000 0.5000 0.500"         rgba="1 0 0 1" contype="1" conaffinity="1"/></body>
        <body name="ob_15_9" pos="-0.5000 -5.5000 0.500">  <geom type="box" size="0.5000 0.5000 0.500"         rgba="1 0 0 1" contype="1" conaffinity="1"/></body>
        <body name="ob_15_10" pos="0.5000 -5.5000 0.500">  <geom type="box" size="0.5000 0.5000 0.500"         rgba="1 0 0 1" contype="1" conaffinity="1"/></body>
        <body name="ob_15_14" pos="4.5000 -5.5000 0.500">  <geom type="box" size="0.5000 0.5000 0.500"         rgba="1 0 0 1" contype="1" conaffinity="1"/></body>
        <body name="ob_15_17" pos="7.5000 -5.5000 0.500">  <geom type="box" size="0.5000 0.5000 0.500"         rgba="1 0 0 1" contype="1" conaffinity="1"/></body>
        <body name="ob_15_19" pos="9.5000 -5.5000 0.500">  <geom type="box" size="0.5000 0.5000 0.500"         rgba="1 0 0 1" contype="1" conaffinity="1"/></body>
        <body name="ob_16_1" pos="-8.5000 -6.5000 0.500">  <geom type="box" size="0.5000 0.5000 0.500"         rgba="1 0 0 1" contype="1" conaffinity="1"/></body>
        <body name="ob_16_3" pos="-6.5000 -6.5000 0.500">  <geom type="box" size="0.5000 0.5000 0.500"         rgba="1 0 0 1" contype="1" conaffinity="1"/></body>
        <body name="ob_16_6" pos="-3.5000 -6.5000 0.500">  <geom type="box" size="0.5000 0.5000 0.500"         rgba="1 0 0 1" contype="1" conaffinity="1"/></body>
        <body name="ob_16_9" pos="-0.5000 -6.5000 0.500">  <geom type="box" size="0.5000 0.5000 0.500"         rgba="1 0 0 1" contype="1" conaffinity="1"/></body>
        <body name="ob_16_13" pos="3.5000 -6.5000 0.500">  <geom type="box" size="0.5000 0.5000 0.500"         rgba="1 0 0 1" contype="1" conaffinity="1"/></body>
        <body name="ob_16_14" pos="4.5000 -6.5000 0.500">  <geom type="box" size="0.5000 0.5000 0.500"         rgba="1 0 0 1" contype="1" conaffinity="1"/></body>
        <body name="ob_16_16" pos="6.5000 -6.5000 0.500">  <geom type="box" size="0.5000 0.5000 0.500"         rgba="1 0 0 1" contype="1" conaffinity="1"/></body>
        <body name="ob_17_1" pos="-8.5000 -7.5000 0.500">  <geom type="box" size="0.5000 0.5000 0.500"         rgba="1 0 0 1" contype="1" conaffinity="1"/></body>
        <body name="ob_17_4" pos="-5.5000 -7.5000 0.500">  <geom type="box" size="0.5000 0.5000 0.500"         rgba="1 0 0 1" contype="1" conaffinity="1"/></body>
        <body name="ob_17_9" pos="-0.5000 -7.5000 0.500">  <geom type="box" size="0.5000 0.5000 0.500"         rgba="1 0 0 1" contype="1" conaffinity="1"/></body>
        <body name="ob_17_12" pos="2.5000 -7.5000 0.500">  <geom type="box" size="0.5000 0.5000 0.500"         rgba="1 0 0 1" contype="1" conaffinity="1"/></body>
        <body name="ob_17_15" pos="5.5000 -7.5000 0.500">  <geom type="box" size="0.5000 0.5000 0.500"         rgba="1 0 0 1" contype="1" conaffinity="1"/></body>
        <body name="ob_17_16" pos="6.5000 -7.5000 0.500">  <geom type="box" size="0.5000 0.5000 0.500"         rgba="1 0 0 1" contype="1" conaffinity="1"/></body>
        <body name="ob_17_17" pos="7.5000 -7.5000 0.500">  <geom type="box" size="0.5000 0.5000 0.500"         rgba="1 0 0 1" contype="1" conaffinity="1"/></body>
        <body name="ob_18_7" pos="-2.5000 -8.5000 0.500">  <geom type="box" size="0.5000 0.5000 0.500"         rgba="1 0 0 1" contype="1" conaffinity="1"/></body>
        <body name="ob_18_12" pos="2.5000 -8.5000 0.500">  <geom type="box" size="0.5000 0.5000 0.500"         rgba="1 0 0 1" contype="1" conaffinity="1"/></body>
        <body name="ob_18_13" pos="3.5000 -8.5000 0.500">  <geom type="box" size="0.5000 0.5000 0.500"         rgba="1 0 0 1" contype="1" conaffinity="1"/></body>
        <body name="ob_18_15" pos="5.5000 -8.5000 0.500">  <geom type="box" size="0.5000 0.5000 0.500"         rgba="1 0 0 1" contype="1" conaffinity="1"/></body>
        <body name="ob_18_16" pos="6.5000 -8.5000 0.500">  <geom type="box" size="0.5000 0.5000 0.500"         rgba="1 0 0 1" contype="1" conaffinity="1"/></body>
        <body name="ob_18_17" pos="7.5000 -8.5000 0.500">  <geom type="box" size="0.5000 0.5000 0.500"         rgba="1 0 0 1" contype="1" conaffinity="1"/></body>
        <body name="ob_18_19" pos="9.5000 -8.5000 0.500">  <geom type="box" size="0.5000 0.5000 0.500"         rgba="1 0 0 1" contype="1" conaffinity="1"/></body>
        <body name="ob_19_4" pos="-5.5000 -9.5000 0.500">  <geom type="box" size="0.5000 0.5000 0.500"         rgba="1 0 0 1" contype="1" conaffinity="1"/></body>
        <body name="ob_19_6" pos="-3.5000 -9.5000 0.500">  <geom type="box" size="0.5000 0.5000 0.500"         rgba="1 0 0 1" contype="1" conaffinity="1"/></body>
        <body name="ob_19_9" pos="-0.5000 -9.5000 0.500">  <geom type="box" size="0.5000 0.5000 0.500"         rgba="1 0 0 1" contype="1" conaffinity="1"/></body>
        <body name="ob_19_16" pos="6.5000 -9.5000 0.500">  <geom type="box" size="0.5000 0.5000 0.500"         rgba="1 0 0 1" contype="1" conaffinity="1"/></body>
        <body name="ob_19_17" pos="7.5000 -9.5000 0.500">  <geom type="box" size="0.5000 0.5000 0.500"         rgba="1 0 0 1" contype="1" conaffinity="1"/></body>
        <body name="ob_19_18" pos="8.5000 -9.5000 0.500">  <geom type="box" size="0.5000 0.5000 0.500"         rgba="1 0 0 1" contype="1" conaffinity="1"/></body>
        <body name="ob_19_19" pos="9.5000 -9.5000 0.500">  <geom type="box" size="0.5000 0.5000 0.500"         rgba="1 0 0 1" contype="1" conaffinity="1"/></body>
    
            <body name="agent_0" pos="0.5000 9.5000 0.5">
                <joint name="agent_0_j1" type="slide" axis="1 0 0"/>
                <joint name="agent_0_j2" type="slide" axis="0 1 0"/>
                <geom  name="agent_geom_0" type="box" size="0.3 0.3 0.3" rgba="1 1 0 1"/>
            </body>
            

            <body name="agent_1" pos="-5.5000 9.5000 0.5">
                <joint name="agent_1_j1" type="slide" axis="1 0 0"/>
                <joint name="agent_1_j2" type="slide" axis="0 1 0"/>
                <geom  name="agent_geom_1" type="box" size="0.3 0.3 0.3" rgba="1 1 0 1"/>
            </body>
            

            <body name="target_0" pos="-5.5000 2.5000 0.25">
                <geom name="target_geom_0" type="sphere" size="0.25"
                      rgba="0 1 0 1" contype="0" conaffinity="0"/>
            </body>
            

            <body name="target_1" pos="-3.5000 9.5000 0.25">
                <geom name="target_geom_1" type="sphere" size="0.25"
                      rgba="0 1 0 1" contype="0" conaffinity="0"/>
            </body>
            
  </worldbody>

</mujoco>