<mujoco model="baseline_lvl4_obs8_seed3005">
    <compiler angle="degree" coordinate="local" inertiafromgeom="true"/>
    <option integrator="RK4" timestep="0.01"/>

    <asset>
        <texture builtin="gradient" height="100" rgb1="0.6 0.8 1" rgb2="0 0 0" type="skybox" width="100"/>
        <texture name="floor_texture" type="2d" builtin="checker" width="100" height="100" rgb1="0 0 0" rgb2="0.8 0.8 0.8"/>
        <material name="MatPlane" reflectance="0.5" shininess="1" specular="1" texrepeat="10 10" texture="floor_texture"/>
    </asset>
    
    <!-- Excluding the contact between the agent and the goal, and the agent and the floor -->
    <contact>
        <exclude body1="agent" body2="goal"/>
        <exclude body1 = "agent" body2 = "floor"/>
    </contact>

    <extension>
        <plugin plugin = "mujoco.pid">
            <instance name = "pid1">
                <config key="kp" value="2"/>
                <config key="ki" value="0"/>
                <config key="kd" value="55"/>
            </instance>
        </plugin>
    </extension>

    <worldbody>
        <light cutoff="100" diffuse="1 1 1" dir="-0 0 -1.3" directional="true" exponent="1" pos="0 0 1.3" specular=".1 .1 .1"/>
        <body name="floor" pos="0 0 0">
            <geom name="floor_geom" type="plane" size="20 20 0.1" material="MatPlane"/>
        </body>
        
        <!-- Goal -->
        <body name="goal" pos="12.000 12.000 0">
            <geom name="goal_geom" type="plane" size="0.5 0.5 1" pos="0 0 0" rgba="1 0 0 1"/>
        </body>

        <!-- Agent -->
        <body name="agent" pos="8.783 12.029 0.25">
            <joint name="j1" type="slide" axis ="1 0 0 "/>
            <joint name="j2" type="slide" axis ="0 1 0 "/>
            <geom name="agent_geom" type="box" size="0.25 0.25 0.250" rgba="1 1 0 1"/>
        </body>

        
    <body name="obstacle1" pos="-6.349 -10.872 0.250">
      <geom name="obstacle1_geom" type="box"
            size="0.800 0.800 0.250"
            rgba="0 1 0 1"/>
    </body>
    <body name="obstacle2" pos="-11.333 8.790 0.250">
      <geom name="obstacle2_geom" type="box"
            size="0.800 0.800 0.250"
            rgba="0 1 0 1"/>
    </body>
    <body name="obstacle3" pos="7.932 -5.703 0.250">
      <geom name="obstacle3_geom" type="box"
            size="0.800 0.800 0.250"
            rgba="0 1 0 1"/>
    </body>
    <body name="obstacle4" pos="16.823 15.277 0.250">
      <geom name="obstacle4_geom" type="box"
            size="0.800 0.800 0.250"
            rgba="0 1 0 1"/>
    </body>
    <body name="obstacle5" pos="-1.857 9.723 0.250">
      <geom name="obstacle5_geom" type="box"
            size="0.800 0.800 0.250"
            rgba="0 1 0 1"/>
    </body>
    <body name="obstacle6" pos="1.195 1.412 0.250">
      <geom name="obstacle6_geom" type="box"
            size="0.800 0.800 0.250"
            rgba="0 1 0 1"/>
    </body>
    <body name="obstacle7" pos="1.918 8.640 0.250">
      <geom name="obstacle7_geom" type="box"
            size="0.800 0.800 0.250"
            rgba="0 1 0 1"/>
    </body>
    <body name="obstacle8" pos="-2.129 -1.769 0.250">
      <geom name="obstacle8_geom" type="box"
            size="0.800 0.800 0.250"
            rgba="0 1 0 1"/>
    </body>
    </worldbody>
    
    <actuator>
        <plugin joint="j1" plugin="mujoco.pid" instance="pid1" />
        <plugin joint="j2" plugin="mujoco.pid" instance="pid1"/>
    </actuator>

  <sensor>
    <distance name="dist1" geom1="agent_geom" geom2="obstacle1_geom" cutoff="1.5"/>
    <distance name="dist2" geom1="agent_geom" geom2="obstacle2_geom" cutoff="1.5"/>
    <distance name="dist3" geom1="agent_geom" geom2="obstacle3_geom" cutoff="1.5"/>
    <distance name="dist4" geom1="agent_geom" geom2="obstacle4_geom" cutoff="1.5"/>
    <distance name="dist5" geom1="agent_geom" geom2="obstacle5_geom" cutoff="1.5"/>
    <distance name="dist6" geom1="agent_geom" geom2="obstacle6_geom" cutoff="1.5"/>
    <distance name="dist7" geom1="agent_geom" geom2="obstacle7_geom" cutoff="1.5"/>
    <distance name="dist8" geom1="agent_geom" geom2="obstacle8_geom" cutoff="1.5"/>
  </sensor>
</mujoco>
