<mujoco model="20x20_BW0_FWx20_AG1_TG1_ATmin12_ATmax15_seed0">
  <option timestep="0.01"/>

  <worldbody>
    <geom name="floor" type="plane" size="20.0 20.0 0.1" rgba="0.5 0.5 0.5 1"/>

    <body name="ob_10_6" pos="-7.0000 -1.0000 0.250">  <geom type="box" size="0.8000 0.8000 0.250"         rgba="1 0 0 1" contype="1" conaffinity="1"/></body>
        <body name="ob_11_7" pos="-5.0000 -3.0000 0.250">  <geom type="box" size="0.8000 0.8000 0.250"         rgba="1 0 0 1" contype="1" conaffinity="1"/></body>
        <body name="ob_12_7" pos="-5.0000 -5.0000 0.250">  <geom type="box" size="0.8000 0.8000 0.250"         rgba="1 0 0 1" contype="1" conaffinity="1"/></body>
        <body name="ob_12_11" pos="3.0000 -5.0000 0.250">  <geom type="box" size="0.8000 0.8000 0.250"         rgba="1 0 0 1" contype="1" conaffinity="1"/></body>
        <body name="ob_13_6" pos="-7.0000 -7.0000 0.250">  <geom type="box" size="0.8000 0.8000 0.250"         rgba="1 0 0 1" contype="1" conaffinity="1"/></body>
        <body name="ob_13_7" pos="-5.0000 -7.0000 0.250">  <geom type="box" size="0.8000 0.8000 0.250"         rgba="1 0 0 1" contype="1" conaffinity="1"/></body>
        <body name="ob_13_8" pos="-3.0000 -7.0000 0.250">  <geom type="box" size="0.8000 0.8000 0.250"         rgba="1 0 0 1" contype="1" conaffinity="1"/></body>
        <body name="ob_13_10" pos="1.0000 -7.0000 0.250">  <geom type="box" size="0.8000 0.8000 0.250"         rgba="1 0 0 1" contype="1" conaffinity="1"/></body>
        <body name="ob_14_8" pos="-3.0000 -9.0000 0.250">  <geom type="box" size="0.8000 0.8000 0.250"         rgba="1 0 0 1" contype="1" conaffinity="1"/></body>
        <body name="ob_14_14" pos="9.0000 -9.0000 0.250">  <geom type="box" size="0.8000 0.8000 0.250"         rgba="1 0 0 1" contype="1" conaffinity="1"/></body>
        <body name="ob_15_16" pos="13.0000 -11.0000 0.250">  <geom type="box" size="0.8000 0.8000 0.250"         rgba="1 0 0 1" contype="1" conaffinity="1"/></body>
        <body name="ob_16_11" pos="3.0000 -13.0000 0.250">  <geom type="box" size="0.8000 0.8000 0.250"         rgba="1 0 0 1" contype="1" conaffinity="1"/></body>
        <body name="ob_16_17" pos="15.0000 -13.0000 0.250">  <geom type="box" size="0.8000 0.8000 0.250"         rgba="1 0 0 1" contype="1" conaffinity="1"/></body>
        <body name="ob_17_13" pos="7.0000 -15.0000 0.250">  <geom type="box" size="0.8000 0.8000 0.250"         rgba="1 0 0 1" contype="1" conaffinity="1"/></body>
        <body name="ob_17_14" pos="9.0000 -15.0000 0.250">  <geom type="box" size="0.8000 0.8000 0.250"         rgba="1 0 0 1" contype="1" conaffinity="1"/></body>
        <body name="ob_17_15" pos="11.0000 -15.0000 0.250">  <geom type="box" size="0.8000 0.8000 0.250"         rgba="1 0 0 1" contype="1" conaffinity="1"/></body>
        <body name="ob_17_19" pos="19.0000 -15.0000 0.250">  <geom type="box" size="0.8000 0.8000 0.250"         rgba="1 0 0 1" contype="1" conaffinity="1"/></body>
        <body name="ob_18_15" pos="11.0000 -17.0000 0.250">  <geom type="box" size="0.8000 0.8000 0.250"         rgba="1 0 0 1" contype="1" conaffinity="1"/></body>
        <body name="ob_18_17" pos="15.0000 -17.0000 0.250">  <geom type="box" size="0.8000 0.8000 0.250"         rgba="1 0 0 1" contype="1" conaffinity="1"/></body>
        <body name="ob_19_17" pos="15.0000 -19.0000 0.250">  <geom type="box" size="0.8000 0.8000 0.250"         rgba="1 0 0 1" contype="1" conaffinity="1"/></body>
    
            <body name="agent_0" pos="-7.0000 -3.0000 0.250">
                <joint name="agent_0_j1" type="slide" axis="1 0 0"/>
                <joint name="agent_0_j2" type="slide" axis="0 1 0"/>
                <geom  name="agent_geom_0" type="box" size="0.25 0.25 0.250" rgba="1 1 0 1"/> 
            </body>
            

            <body name="target_0" pos="17.0000 -17.0000 0.25">
                <geom name="target_geom_0" type="sphere" size="0.25"
                      rgba="0 1 0 1" contype="0" conaffinity="0"/>
            </body>
            
  </worldbody>

</mujoco>