<mujoco model="simple_navigation">
  <compiler angle="degree" coordinate="local" inertiafromgeom="true"/>
  <option integrator="RK4" timestep="0.01"/>

  <asset>
    <texture builtin="gradient" height="100" rgb1="0.6 0.8 1" rgb2="0.1 0.1 0.1" type="skybox" width="100"/>
    <texture name="floor_texture" type="2d" builtin="checker" width="100" height="100" rgb1="0.5 0.5 0.5" rgb2="0.5 0.5 0.5"/>
    <material name="MatPlane" reflectance="0.5" shininess="1" specular="1" texrepeat="10 10" texture="floor_texture"/>
  </asset>

  <contact>
    <exclude body1="agent_1" body2="floor"/>
    <exclude body1="agent_2" body2="floor"/>
  </contact>

  <extension>
    <plugin plugin="mujoco.pid">
      <instance name="pid1">
        <config key="kp" value="2"/>
        <config key="ki" value="0"/>
        <config key="kd" value="55"/>
      </instance>
    </plugin>
  </extension>

  <worldbody>
    <light cutoff="100" diffuse="0.9 0.9 0.9" dir="-0 0 -1.3" directional="true" exponent="1" pos="0 0 1.3" specular=".1 .1 .1"/>
    <body name="floor" pos="0 0 0">
      <geom name="floor_geom" type="plane" size="10 10 0.1" material="MatPlane"/>
    </body>
    <body name="agent_1" pos="6.500000 -0.500000 0.500000">
        <joint name="agent_1_j1" type="slide" axis="1 0 0"/>
        <joint name="agent_1_j2" type="slide" axis="0 1 0"/>
        <geom name="agent_geom_1_geom" type="box" size="0.5 0.5 0.5" rgba="0 0 1 1"/>
    </body>
    <body name="agent_2" pos="-6.500000 9.500000 0.500000">
        <joint name="agent_2_j1" type="slide" axis="1 0 0"/>
        <joint name="agent_2_j2" type="slide" axis="0 1 0"/>
        <geom name="agent_geom_2_geom" type="box" size="0.5 0.5 0.5" rgba="0 0 1 1"/>
    </body>
    <body name="target_1" pos="-6.500000 -9.500000 0.500000">
        <geom name="target_geom_1" type="box" size="0.500000 0.500000 0.500000" rgba="1 1 0 1"/>
    </body>
    <body name="target_2" pos="-9.500000 1.500000 0.500000">
        <geom name="target_geom_2" type="box" size="0.500000 0.500000 0.500000" rgba="1 1 0 1"/>
    </body>
    <body name="target_3" pos="-2.500000 7.500000 0.500000">
        <geom name="target_geom_3" type="box" size="0.500000 0.500000 0.500000" rgba="1 1 0 1"/>
    </body>
    <body name="obstacle_1" pos="0.500000 -8.500000 0.500000">
        <geom name="obstacle_geom_1" type="box" size="0.500000 0.500000 0.500000" rgba="0 0 0 1"/>
    </body>
    <body name="obstacle_2" pos="3.500000 -0.500000 0.500000">
        <geom name="obstacle_geom_2" type="box" size="0.500000 0.500000 0.500000" rgba="0 0 0 1"/>
    </body>
    <body name="obstacle_3" pos="3.500000 6.500000 0.500000">
        <geom name="obstacle_geom_3" type="box" size="0.500000 0.500000 0.500000" rgba="0 0 0 1"/>
    </body>
    <body name="obstacle_4" pos="-1.500000 -4.500000 0.500000">
        <geom name="obstacle_geom_4" type="box" size="0.500000 0.500000 0.500000" rgba="0 0 0 1"/>
    </body>
    <body name="obstacle_5" pos="-1.500000 -2.500000 0.500000">
        <geom name="obstacle_geom_5" type="box" size="0.500000 0.500000 0.500000" rgba="0 0 0 1"/>
    </body>
    <body name="obstacle_6" pos="-3.500000 -4.500000 0.500000">
        <geom name="obstacle_geom_6" type="box" size="0.500000 0.500000 0.500000" rgba="0 0 0 1"/>
    </body>
    <body name="obstacle_7" pos="-0.500000 3.500000 0.500000">
        <geom name="obstacle_geom_7" type="box" size="0.500000 0.500000 0.500000" rgba="0 0 0 1"/>
    </body>
    <body name="obstacle_8" pos="0.500000 -7.500000 0.500000">
        <geom name="obstacle_geom_8" type="box" size="0.500000 0.500000 0.500000" rgba="0 0 0 1"/>
    </body>
    <body name="obstacle_9" pos="3.500000 5.500000 0.500000">
        <geom name="obstacle_geom_9" type="box" size="0.500000 0.500000 0.500000" rgba="0 0 0 1"/>
    </body>
    <body name="obstacle_10" pos="8.500000 1.500000 0.500000">
        <geom name="obstacle_geom_10" type="box" size="0.500000 0.500000 0.500000" rgba="0 0 0 1"/>
    </body>
    <body name="obstacle_11" pos="8.500000 9.500000 0.500000">
        <geom name="obstacle_geom_11" type="box" size="0.500000 0.500000 0.500000" rgba="0 0 0 1"/>
    </body>
    <body name="obstacle_12" pos="6.500000 9.500000 0.500000">
        <geom name="obstacle_geom_12" type="box" size="0.500000 0.500000 0.500000" rgba="0 0 0 1"/>
    </body>
    <body name="obstacle_13" pos="4.500000 -0.500000 0.500000">
        <geom name="obstacle_geom_13" type="box" size="0.500000 0.500000 0.500000" rgba="0 0 0 1"/>
    </body>
    <body name="obstacle_14" pos="-0.500000 -0.500000 0.500000">
        <geom name="obstacle_geom_14" type="box" size="0.500000 0.500000 0.500000" rgba="0 0 0 1"/>
    </body>
    <body name="obstacle_15" pos="-0.500000 -2.500000 0.500000">
        <geom name="obstacle_geom_15" type="box" size="0.500000 0.500000 0.500000" rgba="0 0 0 1"/>
    </body>
    <body name="obstacle_16" pos="-3.500000 -0.500000 0.500000">
        <geom name="obstacle_geom_16" type="box" size="0.500000 0.500000 0.500000" rgba="0 0 0 1"/>
    </body>
    <body name="obstacle_17" pos="-7.500000 -4.500000 0.500000">
        <geom name="obstacle_geom_17" type="box" size="0.500000 0.500000 0.500000" rgba="0 0 0 1"/>
    </body>
    <body name="obstacle_18" pos="8.500000 -5.500000 0.500000">
        <geom name="obstacle_geom_18" type="box" size="0.500000 0.500000 0.500000" rgba="0 0 0 1"/>
    </body>
    <body name="obstacle_19" pos="7.500000 7.500000 0.500000">
        <geom name="obstacle_geom_19" type="box" size="0.500000 0.500000 0.500000" rgba="0 0 0 1"/>
    </body>
    <body name="obstacle_20" pos="-2.500000 5.500000 0.500000">
        <geom name="obstacle_geom_20" type="box" size="0.500000 0.500000 0.500000" rgba="0 0 0 1"/>
    </body>
    <body name="obstacle_21" pos="-5.500000 8.500000 0.500000">
        <geom name="obstacle_geom_21" type="box" size="0.500000 0.500000 0.500000" rgba="0 0 0 1"/>
    </body>
    <body name="obstacle_22" pos="7.500000 2.500000 0.500000">
        <geom name="obstacle_geom_22" type="box" size="0.500000 0.500000 0.500000" rgba="0 0 0 1"/>
    </body>
    <body name="obstacle_23" pos="-3.500000 8.500000 0.500000">
        <geom name="obstacle_geom_23" type="box" size="0.500000 0.500000 0.500000" rgba="0 0 0 1"/>
    </body>
    <body name="obstacle_24" pos="3.500000 8.500000 0.500000">
        <geom name="obstacle_geom_24" type="box" size="0.500000 0.500000 0.500000" rgba="0 0 0 1"/>
    </body>
    <body name="obstacle_25" pos="-0.500000 2.500000 0.500000">
        <geom name="obstacle_geom_25" type="box" size="0.500000 0.500000 0.500000" rgba="0 0 0 1"/>
    </body>
    <body name="obstacle_26" pos="0.500000 -4.500000 0.500000">
        <geom name="obstacle_geom_26" type="box" size="0.500000 0.500000 0.500000" rgba="0 0 0 1"/>
    </body>
    <body name="obstacle_27" pos="-3.500000 -5.500000 0.500000">
        <geom name="obstacle_geom_27" type="box" size="0.500000 0.500000 0.500000" rgba="0 0 0 1"/>
    </body>
    <body name="obstacle_28" pos="4.500000 -7.500000 0.500000">
        <geom name="obstacle_geom_28" type="box" size="0.500000 0.500000 0.500000" rgba="0 0 0 1"/>
    </body>
    <body name="obstacle_29" pos="3.500000 -8.500000 0.500000">
        <geom name="obstacle_geom_29" type="box" size="0.500000 0.500000 0.500000" rgba="0 0 0 1"/>
    </body>
    <body name="obstacle_30" pos="-0.500000 -6.500000 0.500000">
        <geom name="obstacle_geom_30" type="box" size="0.500000 0.500000 0.500000" rgba="0 0 0 1"/>
    </body>
    <geom name="wall_west"  type="box" pos="-10  0  0.5" size="0.05 10   0.5" rgba="0 0 0 1" contype="1" conaffinity="1"/>
    <geom name="wall_east"  type="box" pos=" 10  0  0.5" size="0.05 10   0.5" rgba="0 0 0 1" contype="1" conaffinity="1"/>
    <geom name="wall_south" type="box" pos="  0 -10 0.5" size="10   0.05 0.5" rgba="0 0 0 1" contype="1" conaffinity="1"/>
    <geom name="wall_north" type="box" pos="  0  10 0.5" size="10   0.05 0.5" rgba="0 0 0 1" contype="1" conaffinity="1"/>
  </worldbody>

  <actuator>
    <plugin joint="agent_1_j1" plugin="mujoco.pid" instance="pid1"/>
    <plugin joint="agent_1_j2" plugin="mujoco.pid" instance="pid1"/>
    <plugin joint="agent_2_j1" plugin="mujoco.pid" instance="pid1"/>
    <plugin joint="agent_2_j2" plugin="mujoco.pid" instance="pid1"/>
  </actuator>
</mujoco>
