<mujoco model="lvl3_standard_obs2_d10_seed0">
    <compiler angle="degree" coordinate="local" inertiafromgeom="true"/>
    <option integrator="RK4" timestep="0.01"/>

    <asset>
        <texture builtin="gradient" height="100" rgb1="0.6 0.8 1" rgb2="0 0 0" type="skybox" width="100"/>
        <texture name="floor_texture" type="2d" builtin="checker" width="100" height="100" rgb1="0 0 0" rgb2="0.8 0.8 0.8"/>
        <material name="MatPlane" reflectance="0.5" shininess="1" specular="1" texrepeat="10 10" texture="floor_texture"/>
    </asset>
    
    <!-- Excluding the contact between the agent and the goal, and the agent and the floor -->
    <contact>
        <exclude body1="agent" body2="goal"/>
        <exclude body1 = "agent" body2 = "floor"/>
    </contact>

    <extension>
        <plugin plugin = "mujoco.pid">
            <instance name = "pid1">
                <config key="kp" value="2"/>
                <config key="ki" value="0"/>
                <config key="kd" value="55"/>
            </instance>
        </plugin>
    </extension>


    <worldbody>
        <light cutoff="100" diffuse="1 1 1" dir="-0 0 -1.3" directional="true" exponent="1" pos="0 0 1.3" specular=".1 .1 .1"/>
        <body name="floor" pos="0 0 0">
            <geom name="floor_geom" type="plane" size="20 20 0.1" material="MatPlane"/>
        </body>
        

                <body name="goal" pos="12.0000 -12.0000 0">
            <geom name="goal_geom" type="plane" size="0.5 0.5 1" pos="0 0 0" rgba="1 0 0 1"/>
        </body>
        

                <body name="agent" pos="2.0000 -2.0000 0.250">
            <joint name="j1" type="slide" axis ="1 0 0 "/>
            <joint name="j2" type="slide" axis ="0 1 0 "/>
            <geom name="agent_geom" type="box" size="0.25 0.25 0.250" rgba="1 1 0 1"/>
        </body>


        <body name="ob_10_12" pos="10.0000 -6.0000 0.250">  <geom type="box" size="0.8000 0.8000 0.250"         rgba="1 0 0 1" contype="1" conaffinity="1"/></body>
        <body name="ob_11_11" pos="8.0000 -8.0000 0.250">  <geom type="box" size="0.8000 0.8000 0.250"         rgba="1 0 0 1" contype="1" conaffinity="1"/></body>


    </worldbody>

    <sensor>
<!-- SENSORS -->
    </sensor>

    <actuator>
        <plugin joint="j1" plugin="mujoco.pid" instance="pid1" />
        <plugin joint="j2" plugin="mujoco.pid" instance="pid1"/>
    </actuator>
</mujoco>
