<mujoco model="baseline_lvl5_obs14_seed4010">
    <compiler angle="degree" coordinate="local" inertiafromgeom="true"/>
    <option integrator="RK4" timestep="0.01"/>

    <asset>
        <texture builtin="gradient" height="100" rgb1="0.6 0.8 1" rgb2="0 0 0" type="skybox" width="100"/>
        <texture name="floor_texture" type="2d" builtin="checker" width="100" height="100" rgb1="0 0 0" rgb2="0.8 0.8 0.8"/>
        <material name="MatPlane" reflectance="0.5" shininess="1" specular="1" texrepeat="10 10" texture="floor_texture"/>
    </asset>
    
    <!-- Excluding the contact between the agent and the goal, and the agent and the floor -->
    <contact>
        <exclude body1="agent" body2="goal"/>
        <exclude body1 = "agent" body2 = "floor"/>
    </contact>

    <extension>
        <plugin plugin = "mujoco.pid">
            <instance name = "pid1">
                <config key="kp" value="2"/>
                <config key="ki" value="0"/>
                <config key="kd" value="55"/>
            </instance>
        </plugin>
    </extension>

    <worldbody>
        <light cutoff="100" diffuse="1 1 1" dir="-0 0 -1.3" directional="true" exponent="1" pos="0 0 1.3" specular=".1 .1 .1"/>
        <body name="floor" pos="0 0 0">
            <geom name="floor_geom" type="plane" size="20 20 0.1" material="MatPlane"/>
        </body>
        
        <!-- Goal -->
        <body name="goal" pos="12.000 -12.000 0">
            <geom name="goal_geom" type="plane" size="0.5 0.5 1" pos="0 0 0" rgba="1 0 0 1"/>
        </body>

        <!-- Agent -->
        <body name="agent" pos="9.268 13.975 0.25">
            <joint name="j1" type="slide" axis ="1 0 0 "/>
            <joint name="j2" type="slide" axis ="0 1 0 "/>
            <geom name="agent_geom" type="box" size="0.25 0.25 0.250" rgba="1 1 0 1"/>
        </body>

        
    <body name="obstacle1" pos="0.456 5.002 0.250">
      <geom name="obstacle1_geom" type="box"
            size="0.800 0.800 0.250"
            rgba="0 1 0 1"/>
    </body>
    <body name="obstacle2" pos="7.176 11.771 0.250">
      <geom name="obstacle2_geom" type="box"
            size="0.800 0.800 0.250"
            rgba="0 1 0 1"/>
    </body>
    <body name="obstacle3" pos="17.877 -2.490 0.250">
      <geom name="obstacle3_geom" type="box"
            size="0.800 0.800 0.250"
            rgba="0 1 0 1"/>
    </body>
    <body name="obstacle4" pos="-4.415 -12.753 0.250">
      <geom name="obstacle4_geom" type="box"
            size="0.800 0.800 0.250"
            rgba="0 1 0 1"/>
    </body>
    <body name="obstacle5" pos="-2.378 11.951 0.250">
      <geom name="obstacle5_geom" type="box"
            size="0.800 0.800 0.250"
            rgba="0 1 0 1"/>
    </body>
    <body name="obstacle6" pos="-9.449 16.375 0.250">
      <geom name="obstacle6_geom" type="box"
            size="0.800 0.800 0.250"
            rgba="0 1 0 1"/>
    </body>
    <body name="obstacle7" pos="-5.088 -4.153 0.250">
      <geom name="obstacle7_geom" type="box"
            size="0.800 0.800 0.250"
            rgba="0 1 0 1"/>
    </body>
    <body name="obstacle8" pos="7.286 5.443 0.250">
      <geom name="obstacle8_geom" type="box"
            size="0.800 0.800 0.250"
            rgba="0 1 0 1"/>
    </body>
    <body name="obstacle9" pos="9.805 17.346 0.250">
      <geom name="obstacle9_geom" type="box"
            size="0.800 0.800 0.250"
            rgba="0 1 0 1"/>
    </body>
    <body name="obstacle10" pos="-11.656 11.221 0.250">
      <geom name="obstacle10_geom" type="box"
            size="0.800 0.800 0.250"
            rgba="0 1 0 1"/>
    </body>
    <body name="obstacle11" pos="-13.726 -12.996 0.250">
      <geom name="obstacle11_geom" type="box"
            size="0.800 0.800 0.250"
            rgba="0 1 0 1"/>
    </body>
    <body name="obstacle12" pos="-15.153 -17.014 0.250">
      <geom name="obstacle12_geom" type="box"
            size="0.800 0.800 0.250"
            rgba="0 1 0 1"/>
    </body>
    <body name="obstacle13" pos="-5.898 -8.251 0.250">
      <geom name="obstacle13_geom" type="box"
            size="0.800 0.800 0.250"
            rgba="0 1 0 1"/>
    </body>
    <body name="obstacle14" pos="-16.197 -7.489 0.250">
      <geom name="obstacle14_geom" type="box"
            size="0.800 0.800 0.250"
            rgba="0 1 0 1"/>
    </body>
    </worldbody>
    
    <actuator>
        <plugin joint="j1" plugin="mujoco.pid" instance="pid1" />
        <plugin joint="j2" plugin="mujoco.pid" instance="pid1"/>
    </actuator>

  <sensor>
    <distance name="dist1" geom1="agent_geom" geom2="obstacle1_geom" cutoff="1.5"/>
    <distance name="dist2" geom1="agent_geom" geom2="obstacle2_geom" cutoff="1.5"/>
    <distance name="dist3" geom1="agent_geom" geom2="obstacle3_geom" cutoff="1.5"/>
    <distance name="dist4" geom1="agent_geom" geom2="obstacle4_geom" cutoff="1.5"/>
    <distance name="dist5" geom1="agent_geom" geom2="obstacle5_geom" cutoff="1.5"/>
    <distance name="dist6" geom1="agent_geom" geom2="obstacle6_geom" cutoff="1.5"/>
    <distance name="dist7" geom1="agent_geom" geom2="obstacle7_geom" cutoff="1.5"/>
    <distance name="dist8" geom1="agent_geom" geom2="obstacle8_geom" cutoff="1.5"/>
    <distance name="dist9" geom1="agent_geom" geom2="obstacle9_geom" cutoff="1.5"/>
    <distance name="dist10" geom1="agent_geom" geom2="obstacle10_geom" cutoff="1.5"/>
    <distance name="dist11" geom1="agent_geom" geom2="obstacle11_geom" cutoff="1.5"/>
    <distance name="dist12" geom1="agent_geom" geom2="obstacle12_geom" cutoff="1.5"/>
    <distance name="dist13" geom1="agent_geom" geom2="obstacle13_geom" cutoff="1.5"/>
    <distance name="dist14" geom1="agent_geom" geom2="obstacle14_geom" cutoff="1.5"/>
  </sensor>
</mujoco>
