<mujoco model="simple_navigation">
    <compiler angle="degree" coordinate="local" inertiafromgeom="true"/>
    <option integrator="RK4" timestep="0.01"/>

    <asset>
        <texture builtin="gradient" height="100" rgb1="0.6 0.8 1" rgb2="0 0 0" type="skybox" width="100"/>
        <texture name="floor_texture" type="2d" builtin="checker" width="100" height="100" rgb1="0 0 0" rgb2="0.3 0.3 0.3"/>
        <material name="MatPlane" reflectance="0.5" shininess="1" specular="1" texrepeat="10 10" texture="floor_texture"/>
    </asset>
    
    <!-- Excluding the contact between the agent and the goal, and the agent and the floor -->
    <contact>
        <exclude body1 = "agent_1" body2 = "floor"/>
    </contact>

    <extension>
        <plugin plugin = "mujoco.pid">
            <instance name = "pid1">
                <config key="kp" value="2"/>
                <config key="ki" value="0"/>
                <config key="kd" value="55"/>
            </instance>
        </plugin>
    </extension>


    <worldbody>
        <light cutoff="100" diffuse="1 1 1" dir="-0 0 -1.3" directional="true" exponent="1" pos="0 0 1.3" specular=".1 .1 .1"/>
        <body name="floor" pos="0 0 0">
            <geom name="floor_geom" type="plane" size="20 20 0.1" material="MatPlane"/>
        </body>
        

        <body name="agent_1" pos="0.0 1.0 0.5">
            <joint name="agent_1_j1" type="slide" axis ="1 0 0 "/>
            <joint name="agent_1_j2" type="slide" axis ="0 1 0 "/>
            <geom name="agent_geom_1" type="box" size="0.5 0.5 0.5" rgba="1 1 0 1"/>
        </body>

        <body name="agent_2" pos="-5.0 5.0 0.5">
            <joint name="agent_2_j1" type="slide" axis ="1 0 0 "/>
            <joint name="agent_2_j2" type="slide" axis ="0 1 0 "/>
            <geom name="agent_geom_2" type="box" size="0.5 0.5 0.5" rgba="1 1 0 1"/>
        </body>

        <!-- <body name="target_1" pos="11.0 1.0 0.5">
            <geom name="target_geom_1" type="box" size="0.5 0.5 0.5" rgba="0 1 0 1"/>
        </body>

        <body name="target_2" pos="5.0 -11.0 0.5">
            <geom name="target_geom_2" type="box" size="0.5 0.5 0.5" rgba="0 1 0 1"/>
        </body> -->
 
<!-- OBSTACLES -->

    </worldbody>

    <sensor>
<!-- SENSORS -->
    </sensor>

    <actuator>
        <plugin joint="agent_1_j1" plugin="mujoco.pid" instance="pid1" />
        <plugin joint="agent_1_j2" plugin="mujoco.pid" instance="pid1"/>
        <plugin joint="agent_2_j1" plugin="mujoco.pid" instance="pid1" />
        <plugin joint="agent_2_j2" plugin="mujoco.pid" instance="pid1"/>
    </actuator>
</mujoco>
