<mujoco model="simple_navigation">
    <compiler angle="degree" coordinate="local" inertiafromgeom="true"/>
    <option integrator="RK4" timestep="0.01"/>

    <asset>
        <texture builtin="gradient" height="100" rgb1="0.6 0.8 1" rgb2="0 0 0" type="skybox" width="100"/>
        <texture name="floor_texture" type="2d" builtin="checker" width="100" height="100" rgb1="0 0 0" rgb2="0.8 0.8 0.8"/>
        <material name="MatPlane" reflectance="0.5" shininess="1" specular="1" texrepeat="10 10" texture="floor_texture"/>
    </asset>
    
    <!-- Excluding the contact between the agent and the goal, and the agent and the floor -->
    <contact>
        <exclude body1="agent" body2="goal"/>
        <exclude body1 = "agent" body2 = "floor"/>
    </contact>

    <extension>
        <plugin plugin = "mujoco.pid">
            <instance name = "pid1">
                <config key="kp" value="2"/>
                <config key="ki" value="0"/>
                <config key="kd" value="55"/>
            </instance>
        </plugin>
    </extension>


    <worldbody>
        <light cutoff="100" diffuse="1 1 1" dir="-0 0 -1.3" directional="true" exponent="1" pos="0 0 1.3" specular=".1 .1 .1"/>
        <body name="floor" pos="0 0 0">
            <geom name="floor_geom" type="plane" size="20 20 0.1" material="MatPlane"/>
        </body>
        

        <body name="goal" pos="-11.0 11.0 0">
            <geom name="goal_geom" type="plane" size="0.5 0.5 1" pos="0 0 0" rgba="1 0 0 1"/>
        </body>
        

        <body name="agent" pos="-1.0 -13.0 0.5">
            <joint name="j1" type="slide" axis ="1 0 0 "/>
            <joint name="j2" type="slide" axis ="0 1 0 "/>
            <geom name="agent_geom" type="box" size="0.5 0.5 0.5" rgba="1 1 0 1"/>
        </body>


        <body name="obstacle1" pos="-1.0 7.0 0.5">
            <geom name="obstacle1_geom" type="box" size="0.3 0.3 0.3" rgba="0 1 0 1"/>
        </body>
    
        <body name="obstacle2" pos="13.0 -1.0 0.5">
            <geom name="obstacle2_geom" type="box" size="0.3 0.3 0.3" rgba="0 1 0 1"/>
        </body>
    
        <body name="obstacle3" pos="3.0 3.0 0.5">
            <geom name="obstacle3_geom" type="box" size="0.3 0.3 0.3" rgba="0 1 0 1"/>
        </body>
    
        <body name="obstacle4" pos="7.0 7.0 0.5">
            <geom name="obstacle4_geom" type="box" size="0.3 0.3 0.3" rgba="0 1 0 1"/>
        </body>
    
        <body name="obstacle5" pos="1.0 13.0 0.5">
            <geom name="obstacle5_geom" type="box" size="0.3 0.3 0.3" rgba="0 1 0 1"/>
        </body>
    
        <body name="obstacle6" pos="7.0 -7.0 0.5">
            <geom name="obstacle6_geom" type="box" size="0.3 0.3 0.3" rgba="0 1 0 1"/>
        </body>
    
        <body name="obstacle7" pos="-7.0 -7.0 0.5">
            <geom name="obstacle7_geom" type="box" size="0.3 0.3 0.3" rgba="0 1 0 1"/>
        </body>
    
        <body name="obstacle8" pos="-3.0 9.0 0.5">
            <geom name="obstacle8_geom" type="box" size="0.3 0.3 0.3" rgba="0 1 0 1"/>
        </body>
    
        <body name="obstacle9" pos="-1.0 -11.0 0.5">
            <geom name="obstacle9_geom" type="box" size="0.3 0.3 0.3" rgba="0 1 0 1"/>
        </body>
    
        <body name="obstacle10" pos="5.0 5.0 0.5">
            <geom name="obstacle10_geom" type="box" size="0.3 0.3 0.3" rgba="0 1 0 1"/>
        </body>
    
        <body name="obstacle11" pos="-3.0 13.0 0.5">
            <geom name="obstacle11_geom" type="box" size="0.3 0.3 0.3" rgba="0 1 0 1"/>
        </body>
    
        <body name="obstacle12" pos="-1.0 -7.0 0.5">
            <geom name="obstacle12_geom" type="box" size="0.3 0.3 0.3" rgba="0 1 0 1"/>
        </body>
    
        <body name="obstacle13" pos="5.0 -1.0 0.5">
            <geom name="obstacle13_geom" type="box" size="0.3 0.3 0.3" rgba="0 1 0 1"/>
        </body>
    
        <body name="obstacle14" pos="-11.0 9.0 0.5">
            <geom name="obstacle14_geom" type="box" size="0.3 0.3 0.3" rgba="0 1 0 1"/>
        </body>
    
        <body name="obstacle15" pos="-3.0 -13.0 0.5">
            <geom name="obstacle15_geom" type="box" size="0.3 0.3 0.3" rgba="0 1 0 1"/>
        </body>
    
        <body name="obstacle16" pos="-1.0 -15.0 0.5">
            <geom name="obstacle16_geom" type="box" size="0.3 0.3 0.3" rgba="0 1 0 1"/>
        </body>
    
        <body name="obstacle17" pos="3.0 7.0 0.5">
            <geom name="obstacle17_geom" type="box" size="0.3 0.3 0.3" rgba="0 1 0 1"/>
        </body>
    
        <body name="obstacle18" pos="1.0 -5.0 0.5">
            <geom name="obstacle18_geom" type="box" size="0.3 0.3 0.3" rgba="0 1 0 1"/>
        </body>
    
        <body name="obstacle19" pos="9.0 -13.0 0.5">
            <geom name="obstacle19_geom" type="box" size="0.3 0.3 0.3" rgba="0 1 0 1"/>
        </body>
    
        <body name="obstacle20" pos="-1.0 11.0 0.5">
            <geom name="obstacle20_geom" type="box" size="0.3 0.3 0.3" rgba="0 1 0 1"/>
        </body>
    
        <body name="obstacle21" pos="-11.0 13.0 0.5">
            <geom name="obstacle21_geom" type="box" size="0.3 0.3 0.3" rgba="0 1 0 1"/>
        </body>
    
        <body name="obstacle22" pos="7.0 1.0 0.5">
            <geom name="obstacle22_geom" type="box" size="0.3 0.3 0.3" rgba="0 1 0 1"/>
        </body>
    
        <body name="obstacle23" pos="-9.0 -1.0 0.5">
            <geom name="obstacle23_geom" type="box" size="0.3 0.3 0.3" rgba="0 1 0 1"/>
        </body>
    
        <body name="obstacle24" pos="5.0 -13.0 0.5">
            <geom name="obstacle24_geom" type="box" size="0.3 0.3 0.3" rgba="0 1 0 1"/>
        </body>
    
        <body name="obstacle25" pos="9.0 -5.0 0.5">
            <geom name="obstacle25_geom" type="box" size="0.3 0.3 0.3" rgba="0 1 0 1"/>
        </body>
    
        <body name="obstacle26" pos="-9.0 3.0 0.5">
            <geom name="obstacle26_geom" type="box" size="0.3 0.3 0.3" rgba="0 1 0 1"/>
        </body>
    
        <body name="obstacle27" pos="11.0 1.0 0.5">
            <geom name="obstacle27_geom" type="box" size="0.3 0.3 0.3" rgba="0 1 0 1"/>
        </body>
    
        <body name="obstacle28" pos="-11.0 -3.0 0.5">
            <geom name="obstacle28_geom" type="box" size="0.3 0.3 0.3" rgba="0 1 0 1"/>
        </body>
    
        <body name="obstacle29" pos="1.0 -7.0 0.5">
            <geom name="obstacle29_geom" type="box" size="0.3 0.3 0.3" rgba="0 1 0 1"/>
        </body>
    
        <body name="obstacle30" pos="-11.0 5.0 0.5">
            <geom name="obstacle30_geom" type="box" size="0.3 0.3 0.3" rgba="0 1 0 1"/>
        </body>
    

    </worldbody>

    <sensor>
        <distance name="dist1" geom1="agent_geom" geom2="obstacle1_geom" cutoff="1.5"/>
        <distance name="dist2" geom1="agent_geom" geom2="obstacle2_geom" cutoff="1.5"/>
        <distance name="dist3" geom1="agent_geom" geom2="obstacle3_geom" cutoff="1.5"/>
        <distance name="dist4" geom1="agent_geom" geom2="obstacle4_geom" cutoff="1.5"/>
        <distance name="dist5" geom1="agent_geom" geom2="obstacle5_geom" cutoff="1.5"/>
        <distance name="dist6" geom1="agent_geom" geom2="obstacle6_geom" cutoff="1.5"/>
        <distance name="dist7" geom1="agent_geom" geom2="obstacle7_geom" cutoff="1.5"/>
        <distance name="dist8" geom1="agent_geom" geom2="obstacle8_geom" cutoff="1.5"/>
        <distance name="dist9" geom1="agent_geom" geom2="obstacle9_geom" cutoff="1.5"/>
        <distance name="dist10" geom1="agent_geom" geom2="obstacle10_geom" cutoff="1.5"/>
        <distance name="dist11" geom1="agent_geom" geom2="obstacle11_geom" cutoff="1.5"/>
        <distance name="dist12" geom1="agent_geom" geom2="obstacle12_geom" cutoff="1.5"/>
        <distance name="dist13" geom1="agent_geom" geom2="obstacle13_geom" cutoff="1.5"/>
        <distance name="dist14" geom1="agent_geom" geom2="obstacle14_geom" cutoff="1.5"/>
        <distance name="dist15" geom1="agent_geom" geom2="obstacle15_geom" cutoff="1.5"/>
        <distance name="dist16" geom1="agent_geom" geom2="obstacle16_geom" cutoff="1.5"/>
        <distance name="dist17" geom1="agent_geom" geom2="obstacle17_geom" cutoff="1.5"/>
        <distance name="dist18" geom1="agent_geom" geom2="obstacle18_geom" cutoff="1.5"/>
        <distance name="dist19" geom1="agent_geom" geom2="obstacle19_geom" cutoff="1.5"/>
        <distance name="dist20" geom1="agent_geom" geom2="obstacle20_geom" cutoff="1.5"/>
        <distance name="dist21" geom1="agent_geom" geom2="obstacle21_geom" cutoff="1.5"/>
        <distance name="dist22" geom1="agent_geom" geom2="obstacle22_geom" cutoff="1.5"/>
        <distance name="dist23" geom1="agent_geom" geom2="obstacle23_geom" cutoff="1.5"/>
        <distance name="dist24" geom1="agent_geom" geom2="obstacle24_geom" cutoff="1.5"/>
        <distance name="dist25" geom1="agent_geom" geom2="obstacle25_geom" cutoff="1.5"/>
        <distance name="dist26" geom1="agent_geom" geom2="obstacle26_geom" cutoff="1.5"/>
        <distance name="dist27" geom1="agent_geom" geom2="obstacle27_geom" cutoff="1.5"/>
        <distance name="dist28" geom1="agent_geom" geom2="obstacle28_geom" cutoff="1.5"/>
        <distance name="dist29" geom1="agent_geom" geom2="obstacle29_geom" cutoff="1.5"/>
        <distance name="dist30" geom1="agent_geom" geom2="obstacle30_geom" cutoff="1.5"/>
    </sensor>

    <actuator>
        <plugin joint="j1" plugin="mujoco.pid" instance="pid1" />
        <plugin joint="j2" plugin="mujoco.pid" instance="pid1"/>
    </actuator>
</mujoco>
