<mujoco model="lvl5_corridor_obs15_d5_depth3_seed0">
    <compiler angle="degree" coordinate="local" inertiafromgeom="true"/>
    <option integrator="RK4" timestep="0.01"/>

    <asset>
        <texture builtin="gradient" height="100" rgb1="0.6 0.8 1" rgb2="0 0 0" type="skybox" width="100"/>
        <texture name="floor_texture" type="2d" builtin="checker" width="100" height="100" rgb1="0 0 0" rgb2="0.8 0.8 0.8"/>
        <material name="MatPlane" reflectance="0.5" shininess="1" specular="1" texrepeat="10 10" texture="floor_texture"/>
    </asset>
    
    <!-- Excluding the contact between the agent and the goal, and the agent and the floor -->
    <contact>
        <exclude body1="agent" body2="goal"/>
        <exclude body1 = "agent" body2 = "floor"/>
    </contact>

    <extension>
        <plugin plugin = "mujoco.pid">
            <instance name = "pid1">
                <config key="kp" value="2"/>
                <config key="ki" value="0"/>
                <config key="kd" value="55"/>
            </instance>
        </plugin>
    </extension>


    <worldbody>
        <light cutoff="100" diffuse="1 1 1" dir="-0 0 -1.3" directional="true" exponent="1" pos="0 0 1.3" specular=".1 .1 .1"/>
        <body name="floor" pos="0 0 0">
            <geom name="floor_geom" type="plane" size="20 20 0.1" material="MatPlane"/>
        </body>
        

                <body name="goal" pos="12.0000 -12.0000 0">
            <geom name="goal_geom" type="plane" size="0.5 0.5 1" pos="0 0 0" rgba="1 0 0 1"/>
        </body>
        

                <body name="agent" pos="10.0000 -4.0000 0.250">
            <joint name="j1" type="slide" axis ="1 0 0 "/>
            <joint name="j2" type="slide" axis ="0 1 0 "/>
            <geom name="agent_geom" type="box" size="0.25 0.25 0.250" rgba="1 1 0 1"/>
        </body>


        <body name="obstacle1" pos="3.9582 2.0015 0.250">  <geom name="obstacle1_geom" type="box" size="0.8000 0.8000 0.250" rgba="0 1 0 1"/></body>
        <body name="obstacle2" pos="5.8083 2.0810 0.250">  <geom name="obstacle2_geom" type="box" size="0.8000 0.8000 0.250" rgba="0 1 0 1"/></body>
        <body name="obstacle3" pos="7.9262 -0.0963 0.250">  <geom name="obstacle3_geom" type="box" size="0.8000 0.8000 0.250" rgba="0 1 0 1"/></body>
        <body name="obstacle4" pos="5.8115 -1.8016 0.250">  <geom name="obstacle4_geom" type="box" size="0.8000 0.8000 0.250" rgba="0 1 0 1"/></body>
        <body name="obstacle5" pos="7.8515 -1.9884 0.250">  <geom name="obstacle5_geom" type="box" size="0.8000 0.8000 0.250" rgba="0 1 0 1"/></body>
        <body name="obstacle6" pos="11.8178 -1.8526 0.250">  <geom name="obstacle6_geom" type="box" size="0.8000 0.8000 0.250" rgba="0 1 0 1"/></body>
        <body name="obstacle7" pos="12.1900 -3.8503 0.250">  <geom name="obstacle7_geom" type="box" size="0.8000 0.8000 0.250" rgba="0 1 0 1"/></body>
        <body name="obstacle8" pos="9.9953 -5.9722 0.250">  <geom name="obstacle8_geom" type="box" size="0.8000 0.8000 0.250" rgba="0 1 0 1"/></body>
        <body name="obstacle9" pos="12.1757 -5.9512 0.250">  <geom name="obstacle9_geom" type="box" size="0.8000 0.8000 0.250" rgba="0 1 0 1"/></body>


    </worldbody>

    <sensor>
<!-- SENSORS -->
    
        <distance name="dist1" geom1="agent_geom" geom2="obstacle1_geom" cutoff="1.5"/>
        <distance name="dist2" geom1="agent_geom" geom2="obstacle2_geom" cutoff="1.5"/>
        <distance name="dist3" geom1="agent_geom" geom2="obstacle3_geom" cutoff="1.5"/>
        <distance name="dist4" geom1="agent_geom" geom2="obstacle4_geom" cutoff="1.5"/>
        <distance name="dist5" geom1="agent_geom" geom2="obstacle5_geom" cutoff="1.5"/>
        <distance name="dist6" geom1="agent_geom" geom2="obstacle6_geom" cutoff="1.5"/>
        <distance name="dist7" geom1="agent_geom" geom2="obstacle7_geom" cutoff="1.5"/>
        <distance name="dist8" geom1="agent_geom" geom2="obstacle8_geom" cutoff="1.5"/>
        <distance name="dist9" geom1="agent_geom" geom2="obstacle9_geom" cutoff="1.5"/>
</sensor>

    <actuator>
        <plugin joint="j1" plugin="mujoco.pid" instance="pid1" />
        <plugin joint="j2" plugin="mujoco.pid" instance="pid1"/>
    </actuator>
</mujoco>
